Workbook

Sheet Daily Activity w Contents
A1: #VALUE! | G1: Daily Activity Tracking Report | U1: Date | V1: 46262
U2: Report No. | V2: 5.04-F.10
A3: Daily Project Based Repair Rates (%) | F3: 2 | G3: Incoming Materials (Gelen Bant ve Plakalar) | J3: Total Manufactured Pipe Quantity (Toplam Boru Uretim Adedi) | R3: Total Repaired Pipe Quantity (Toplam Tamiri Tamamlanan Boru Adedi)
A4: 01-117KH Ø 60 " x 1.25" - 23 Pipes | F4: 3
A5: 06-131TS Ø 42 " x 1" - 72 Pipes | F5: 4 | G5: Dimensions | H5: Qty. | I5: Manufacturer | J5: Machine A | M5: Machine B | R5: Project No. | S5: Dimensions | T5: Pipe # | U5: Project No. | V5: Dimensions | W5: Pipe #
A6: 10-107JT Ø72" x 1"- 226 Pipes | F6: 5 | J6: Dimensions | L6: Pipe No. | M6: Dimensions | Q6: Pipe No.
A7: 01-116 Ø42" x 1"- 48 Pipes | F7: 6 | H7: - | J7: 01-118 (Ø36" x 0.625") | L7: 354 … 371 (18 pcs.) | M7: 01-117 (Ø60" x 1.25") | Q7: 16 - 17 (2 pcs.) | R7: 02-123 | S7: Ø42" x 1" | T7: 100 - 79 66 - 93 | U7: 11-111 | V7: Ø84" x 0.75" | W7: 11 - 8
A8: 11-111 Ø78" x .5"- 3 Pipes | F8: 7
A9: 11-111 Ø84" x .75"- 24 Pipes | F9: 8
A10: 11-111 Ø96" x .75"- 6 Pipes | F10: 9 | R10: 01-117 | S10: Ø60" x 1.25" | T10: 10 | U10: 01-118 | V10: Ø36" x 0.625" | W10: 11 pcs.
A11: 10-108 Ø78" x .5"- 15 Pipes | F11: 10
A12: 10-108 Ø96" x .625"- 4 Pipes | F12: 11 | R12: 10-108 | S12: Ø54" x 0.375" | T12: 4 - 6
A13: 10-108 Ø60" x .375"- 22 Pipes | F13: 12
A14: 10-108 Ø66" x .375"- 209 Pipes | F14: 13 | G14: Total JDF-HDM numbered PLATE quantity is 4900. (PLT4900) | J14: 01-118 (Ø36" x 0.625") | M14: 01-117 (Ø60" x 1.25") | R14: Total repaired pipe quantity:
A15: 10-108 Ø54" x .375"- 6 Pipes | F15: 14 | J15: 371/676 | M15: 17/23 | R15: 108 for 10-107 118 for 02-123 | U15: 19 for 06-131 (42" x 1") 85 for 01-118
A16: 02-123 Ø42" x 1"- 120 Pipes | F16: 15 | G16: Total JDF-HDM numbered COIL quantity is 4591. (HDM4591) | J16: 10-108 (Ø54" x 0.375") | M16: 06-131 (Ø42" x 1")
A17: 01-118 Ø36" x .625"- 676 Pipes | F17: 16-18 | J17: 6/6 | M17: 72/72
A18: Total Clutch/Accessory Completed Process Quantity (Toplam Clutch/Aksesuar Tamamlanan Proses Adedi) | L18: Total Coated Pipe Quantity (Toplam Boyanan Boru Adedi) | S18: Total Shipped Pipe Quantity (Toplam Sevki Yapilan Boru Adedi)
A20: Ring/Shoe | G20: Clutch | L20: Project No. | N20: Qty. | P20: Coating Details | S20: Project No. | T20: Dimensions / Quantity | W20: Shipment
A21: Project No. | C21: Qty. | D21: Dimensions - Process Type | G21: Project No. | I21: Qty. | J21: Dimensions - Process Type
A23: 01-118 | C23: 11 pcs. | D23: Weld-Out | G23: 10-107 | I23: 1 pc. | J23: Weld-Out | L23: 10-107 | N23: 1 pc. | P23: Bitumastic 300M | S23: 02-123 | T23: Ø42" x 1" - 3 PCS. | W23: WATCO
G24: 01-118 | I24: 2 pcs. | J24: Tack Weld | S24: 10-107 | T24: Ø72" x 1" - 1 PCS.
S25: 10-108 | T25: Ø66" x 0.375" - 2 PCS. | W25: CUSTOMER
L26: 10-108 Ø54" x 0.375" | N26: 3 pcs. | P26: Carbozinc 11
A31: 10-107 Project | L31: 10-107 Project | S31: 10-107
A32: 107 Pipes' Clutch Tack Welding Completed (Montaj) 105 Pipes' Clutch Weld Out Completed (Kaynak) | L32: Total 300M Coated 105 pcs. | S32: To Watco 104 pcs.
L33: 10-108 Project | S33: 02-123
L34: (Ø 60 " x 0.375 ") 22 pcs. (Ø 72" x 0.5") 7 pcs. (Ø 68" x 0.375") 103 pcs. | O34: (Ø84" x 0.5") 14 pcs. (Ø 78" x 0.5") 3 pcs. (Ø 66" x 0.375") 209 pcs. | S34: To Watco 114 pcs.
S35: 01-116 (42" x 1")
S36: To Watco 48 pcs.
A38: LR: Lately Reported

Sheet Daily Repair Rate (Old)
F1: Daily Project Based Repair Rates (%) | O1: Date | P1: 46182
A3: # | B3: Project No. | E3: Dimensions | H3: Qty. | I3: Project's Total Pipe Length (ft) | J3: Repaired Pipes' Total Length (ft) | K3: Repaired Pipes' Total Spiral Length (ft) | L3: Total Repair Amount (mt) | M3: Total Repair Amount with Skelp-end Welds (mt) | N3: Project Status | O3: Repair Ratio (%) | P3: Repair Ratio Inc. Skelp-end Welds (%)
A4: 1 | B4: 2025Q-05-095 #2 | E4: Ø72"x1" | H4: 190 | I4: 9180 | J4: 7980 | K4: =(72*3.1415/59)*(J4) -> 30592.885 | L4: 406.92 | M4: 555.42 | N4: IN PROGRESS | O4: 0.0436 | P4: 0.0596
A5: 2 | B5: 2025Q-10-108JT | E5: Ø60"x.375" | H5: 22 | I5: 1220 | J5: 290 | K5: =(60*3.1415/64)*(J5) -> 854.09531 | L5: 14.35 | M5: 15.85 | N5: IN PROGRESS | O5: 0.0551 | P5: 0.0609
A6: 3 | B6: 2025Q-10-108JT | E6: Ø66"x.375" | H6: 204 | I6: 10240 | J6: 5055 | K6: =(66*3.1415/64)*(J6) -> 16376.541 | L6: 58.05 | M6: 91.05 | N6: IN PROGRESS | O6: 0.0116 | P6: 0.0182
A7: 4 | B7: 2026Q-10-108JT | E7: Ø68"x.375" | H7: 108 | I7: 5270 | J7: 3285 | K7: =(68*3.1415/64)*(J7) -> 10964.817 | L7: 18.97 | M7: 42.97 | N7: IN PROGRESS | O7: 0.0057 | P7: 0.0129
A8: 5 | B8: 2026Q-10-108JT | E8: Ø78"x0.5" | H8: 16 | I8: 970 | J8: 210 | K8: =(78*3.1415/44)*(J8) -> 1169.4948 | L8: 2.46 | M8: 5.46 | N8: IN PROGRESS | O8: 0.0069 | P8: 0.0153
A9: 6 | B9: 2026Q-10-108JT | E9: Ø84"x0.5" | H9: 16 | I9: 875 | J9: 875 | K9: =(84*3.1415/59)*(J9) -> 3913.5636 | L9: 6.1 | M9: 15.1 | N9: COMPLETED | O9: 0.0051 | P9: 0.0094
A10: 7 | B10: 2026Q-10-108JT | E10: Ø72" Combined | H10: 8 | I10: 440 | J10: 440 | K10: =(72*3.1415/44)*(J10) -> 2261.88 | L10: 7.21 | M10: 10.21 | N10: COMPLETED | O10: 0.0105 | P10: 0.0148
A11: 8 | B11: 2026Q-10-108JT | E11: Ø84" Combined | H11: 6 | I11: 235 | J11: 235 | K11: =(84*3.1415/59)*(J11) -> 1051.0714 | L11: 2.46 | M11: 3.96 | N11: COMPLETED | O11: 0.0077 | P11: 0.0124
A12: 9 | B12: 2026Q-10-108JT | E12: Ø90" Combined | H12: 12 | I12: 500 | J12: 500 | K12: =(90*3.1415/59)*(J12) -> 2396.0593 | L12: 39.85 | M12: 47.35 | N12: COMPLETED | O12: 0.0546 | P12: 0.0648
A13: 10 | B13: 2026Q-11-111JT | E13: Ø84"x0.5" | H13: 39 | I13: 2085 | J13: 2085 | K13: =(84*3.1415/59)*(J13) -> 9325.4629 | L13: 16.38 | M13: 40.38 | N13: COMPLETED | O13: 0.0058 | P13: 0.0142
A14: 11 | B14: 2026Q-11-111JT | E14: Ø90" Combined | H14: 54 | I14: 2760 | J14: 2760 | K14: =(90*3.1415/59)*(J14) -> 13226.247 | L14: 74.07 | M14: 113.07 | N14: COMPLETED | O14: 0.0184 | P14: 0.028
A15: 12 | B15: 2025Q-12-112SN | E15: Ø60"x1" | H15: 30 | I15: 2940 | J15: 1274 | K15: =(60*3.1415/59)*(J15) -> 4070.1061 | L15: 125.64 | M15: 145.14 | N15: IN PROGRESS | O15: 0.1013 | P15: 0.117
A16: 13 | B16: 2025Q-10-107JT | E16: Ø72"x1" | H16: 226 | I16: 29305.4 | J16: 6353.83 | K16: =(72*3.1415/59)*(J16) -> 24358.646 | L16: 148.76 | M16: 274.76 | N16: IN PROGRESS | O16: 0.02 | P16: 0.037
A17: 14 | B17: 2025Q-12-113SN | E17: Ø66"x.75" | H17: 25 | I17: 3125 | J17: 3125 | K17: =(66*3.1415/59)*(J17) -> 10981.939 | L17: 52.99 | M17: 90.49 | N17: COMPLETED | O17: 0.0158 | P17: 0.027
A18: 15 | B18: 2025Q-05-93 (PT) | E18: Ø54"x1.5" | H18: 47 | I18: 8041 | J18: 3772 | K18: 12704.1 | L18: 344.39 | M18: 619.79 | N18: IN PROGRESS | O18: 0.0889 | P18: 0.1601
A19: 16 | B19: 2026Q-05-126TS | E19: Ø42"x1" | H19: 8 | I19: 480 | J19: 480 | K19: =(42*3.1415/59)*(J19) -> 1073.4346 | L19: 12.42 | M19: 16.92 | N19: COMPLETED | O19: 0.038 | P19: 0.0517
A20: 17 | B20: 2025Q-05-93 (HDD) | E20: Ø36"x.75" | H20: 14 | I20: 1624 | J20: 1624 | K20: =(36*3.1415/59)*(J20) -> 3112.9603 | L20: 20.7 | M20: 26.7 | N20: COMPLETED | O20: 0.0218 | P20: 0.0281
A21: 18 | B21: 2025Q-10-105 | E21: Ø36"x.75" | H21: 89 | I21: 5843 | J21: 5843 | K21: =(36*3.1415/59)*(J21) -> 11200.14 | L21: 72.38 | M21: 108.38 | N21: COMPLETED | O21: 0.0212 | P21: 0.0317
A22: 19 | B22: 2026Q-01-115NN | E22: Ø60"x1" | H22: 27 | I22: 3807 | J22: 3807 | K22: =(60*3.1415/59)*(J22) -> 12162.397 | L22: 75.69 | M22: 131.19 | N22: COMPLETED | O22: 0.0204 | P22: 0.0354
A23: 20 | B23: 2026Q-01-116SN | E23: Ø42"x1" | H23: 48 | I23: 6255.84 | J23: 3127.92 | K23: =(42*3.1415/59)*(J23) -> 6995.0364 | L23: 55.62 | M23: 91.62 | N23: IN PROGRESS | O23: 0.0261 | P23: 0.043
A24: 21 | B24: 2026Q-01-116SN | E24: Ø36"x1" | H24: 53 | I24: 6332 | J24: 2851.5 | K24: =(36*3.1415/59)*(J24) -> 5465.8905 | L24: 49 | M24: 77.5 | N24: IN PROGRESS | O24: 0.0294 | P24: 0.0465
A25: 22 | B25: 2026Q-05-128RZ | E25: Ø36"x0.75" | H25: 18 | I25: 990 | J25: 420 | K25: =(36*3.1415/59)*(J25) -> 805.07593 | L25: 5.79 | M25: 7.29 | N25: IN PROGRESS | O25: 0.0236 | P25: 0.0297
A26: 23
A27: 24
A28: 25
A29: Repair Rate Calculation
A30: Overall Repair Rate (2026) Total of 35 Projects Included Since The Beginning of 2026 | J30: =C44 -> 0.023934201 | M30: Inc. Skelp-end Welds (2026) | O30: =F44 -> 0.043971824
A39: ANNUAL REPAIR RATES | J39: PROJECTS | K39: 46176 | L39: 46177 | M39: 46178 | N39: 46179 | O39: 46181 | P39: 46182
A40: YEAR | C40: REPAIR RATIO | F40: INCLUDING SKELP WELD | J40: 05-095 | K40: 0.0436 | L40: 0.0436 | M40: 0.0436 | N40: 0.0436 | O40: 0.0436 | P40: 0.0436
A41: OVERALL | C41: =((SUM(G49:G177)*3.281+SUM(L4:L28)*3.281))/((SUM(F49:F177)+SUM(K4:K28))) -> 0.027902692 | F41: =((SUM(H49:H177)*3.281+SUM(M4:M28)*3.281))/((SUM(F49:F177)+SUM(K4:K28))) -> 0.050105277 | J41: 05-093 (Pipeway) | K41: 0.086 | L41: 0.0847 | M41: 0.0847 | N41: 0.0847 | O41: 0.0889 | P41: 0.0889
A42: 2022-2024 | C42: =((SUM(G49:G79)*3.281))/((SUM(F49:F79))) -> 0.034274572 | F42: =((SUM(H49:H79)*3.281))/((SUM(F49:F79))) -> 0.064430828 | J42: 10-107JT | K42: 0.02 | L42: 0.02 | M42: 0.02 | N42: 0.02 | O42: 0.02 | P42: 0.02
A43: 2025 | C43: =((SUM(G80:G131)*3.281))/((SUM(F80:F131))) -> 0.023084083 | F43: =((SUM(H80:H131)*3.281))/((SUM(F80:F131))) -> 0.03713042 | J43: 01-116SN (42") | K43: 0.0261 | L43: 0.0261 | M43: 0.0261 | N43: 0.0261 | O43: 0.0261 | P43: 0.0261
A44: 2026 | C44: =((SUM(G132:G177)*3.281)+(SUM(L4:L28)*3.281))/((SUM(F132:F177)+SUM(K4:K28))) -> 0.023934201 | F44: =((SUM(H132:H177)*3.281+SUM(M4:M28)*3.281))/((SUM(F132:F177)+SUM(K4:K28))) -> 0.043971824 | J44: 01-116SN (36") | K44: 0.0294 | L44: 0.0294 | M44: 0.0294 | N44: 0.0294 | O44: 0.0294 | P44: 0.0294
J45: 12-112SN (60") | K45: 0.1083 | L45: 0.103 | M45: 0.103 | N45: 0.103 | O45: 0.1013 | P45: 0.1013
A46: YEAR | B46: Overall Repair Rates | J46: 05-0128RZ | O46: 0.0051 | P46: 0.0236
B47: Proj. Name | F47: Repaired Pipes' Total Spiral Length (ft) | G47: Total Repair Amount (mt) | H47: Total Repair Amount with Skelp-end Welds (mt) | J47: Total Rate | K47: 0.0239 | L47: 0.0239 | M47: 0.0239 | N47: 0.0239 | O47: 0.0239 | P47: 0.0239
A49: 2022-2024 | B49: Hawaii Barge 1 140 Pipes - Ø 85 " x 1.4 " | F49: 52315.138 | G49: 751.35 | H49: 2086.35
B50: Hawaii Barge 2 97 Pipes - Ø 85 " x 1.4 " | F50: 37762.139 | G50: 587.08 | H50: 1544.08
...

Sheet Daily Repair Rate
F1: Daily Project Based Repair Rates (%) | O1: Date | P1: 46262
A3: Ongoing & Recently Completed Productions with Plate
A4: # | B4: Project No. | E4: Dimensions | H4: Qty. | I4: Project's Total Pipe Length (ft) | J4: Repaired Pipes' Total Length (ft) | K4: Repaired Pipes' Total Spiral Length (ft) | L4: Total Repair Amount (mt) | M4: Total Repair Amount with Skelp-end Welds (mt) | N4: Project Status | O4: Repair Ratio (%) | P4: Repair Ratio Inc. Skelp-end Welds (%)
A5: 1 | B5: 12-112 (54 x 1.2) | E5: Ø54"x1.2" | H5: 4 | I5: 160 | J5: 160 | K5: =(54*3.1415/60)*(J5) -> 452.376 | L5: 14.12 | M5: 26.12 | N5: COMPLETED | O5: 0.1024 | P5: 0.1895
A6: 2 | B6: 2025Q-05-93 (PT) | E6: Ø54"x1.5" | H6: 49 | I6: 8041 | J6: 8041 | K6: 33104 | L6: 739.53 | M6: 1308.33 | N6: COMPLETED | O6: 0.0733 | P6: 0.1297
A7: 3 | B7: 01-117KH | E7: Ø60"x1.25" | H7: 23 | I7: 1881 | J7: 331 | K7: 974.85 | L7: 10.87 | M7: 34.87 | N7: IN PROGRESS | O7: 0.0366 | P7: 0.1174
A8: 4
A9: 5
A10: 6
A11: 7
A12: 8
A13: 9
A14: 10
A15: Ongoing & Recently Completed Productions with Coil
A16: # | B16: Project No. | E16: Dimensions | H16: Qty. | I16: Project's Total Pipe Length (ft) | J16: Repaired Pipes' Total Length (ft) | K16: Repaired Pipes' Total Spiral Length (ft) | L16: Total Repair Amount (mt) | M16: Total Repair Amount with Skelp-end Welds (mt) | N16: Project Status | O16: Repair Ratio (%) | P16: Repair Ratio Inc. Skelp-end Welds (%)
A17: 1 | B17: 2025Q-10-108JT | E17: Ø54"x.375" | H17: 6 | I17: 210 | J17: 210 | K17: =(54*3.1415/59)*(J17) -> 603.80695 | L17: 7.52 | M17: 7.52 | N17: IN PROGRESS | O17: 0.0409 | P17: 0.0409
A18: 2 | B18: 2025Q-10-108JT | E18: Ø60"x.375" | H18: 22 | I18: 1220 | J18: 1220 | K18: =(60*3.1415/64)*(J18) -> 3593.0906 | L18: 25.93 | M18: 31.93 | N18: IN PROGRESS | O18: 0.0236 | P18: 0.029
A19: 3 | B19: 2025Q-10-108JT | E19: Ø66"x.375" | H19: 209 | I19: 10490 | J19: 10490 | K19: =(66*3.1415/64)*(J19) -> 33984.158 | L19: 111.06 | M19: 180.06 | N19: COMPLETED | O19: 0.0107 | P19: 0.0174
A20: 4 | B20: 2026Q-10-108JT | E20: Ø68"x.375" | H20: 108 | I20: 5270 | J20: 5270 | K20: =(68*3.1415/64)*(J20) -> 17590.437 | L20: 53.32 | M20: 90.82 | N20: IN PROGRESS | O20: 0.0099 | P20: 0.0169
A21: 5 | B21: 2026Q-10-108JT | E21: Ø78"x0.5" | H21: 15 | I21: 905 | J21: 455 | K21: =(78*3.1415/44)*(J21) -> 2533.9053 | L21: 6.4 | M21: 10.9 | N21: IN PROGRESS | O21: 0.0083 | P21: 0.0141
A22: 6 | B22: 2026Q-10-108JT | E22: Ø84"x0.5" | H22: 16 | I22: 875 | J22: 875 | K22: =(84*3.1415/59)*(J22) -> 3913.5636 | L22: 6.1 | M22: 15.1 | N22: COMPLETED | O22: 0.0051 | P22: 0.0094
A23: 7 | B23: 2026Q-10-108JT | E23: Ø72" Combined | H23: 8 | I23: 440 | J23: 440 | K23: =(72*3.1415/44)*(J23) -> 2261.88 | L23: 7.21 | M23: 10.21 | N23: COMPLETED | O23: 0.0105 | P23: 0.0148
A24: 8 | B24: 2026Q-10-108JT | E24: Ø84" Combined | H24: 6 | I24: 235 | J24: 235 | K24: =(84*3.1415/59)*(J24) -> 1051.0714 | L24: 2.46 | M24: 3.96 | N24: COMPLETED | O24: 0.0077 | P24: 0.0124
A25: 9 | B25: 2026Q-10-108JT | E25: Ø90" Combined | H25: 12 | I25: 500 | J25: 500 | K25: =(90*3.1415/59)*(J25) -> 2396.0593 | L25: 39.85 | M25: 47.35 | N25: COMPLETED | O25: 0.0546 | P25: 0.0648
A26: 10 | B26: 2026Q-11-111JT | E26: Ø84"x0.5" | H26: 39 | I26: 2085 | J26: 2085 | K26: =(84*3.1415/59)*(J26) -> 9325.4629 | L26: 16.38 | M26: 40.38 | N26: COMPLETED | O26: 0.0058 | P26: 0.0142
A27: 10 | B27: 2026Q-11-111JT | E27: Ø84"x0.75" | H27: 24 | I27: 1005 | J27: 542.5 | K27: =(84*3.1415/59)*(J27) -> 2426.4094 | L27: 17.65 | M27: 28.15 | N27: IN PROGRESS | O27: 0.0239 | P27: 0.0381
A28: 11 | B28: 2026Q-11-111JT | E28: Ø90" Combined | H28: 54 | I28: 2760 | J28: 2760 | K28: =(90*3.1415/59)*(J28) -> 13226.247 | L28: 74.07 | M28: 113.07 | N28: COMPLETED | O28: 0.0184 | P28: 0.028
A29: 12 | B29: 2025Q-12-112SN | E29: Ø60"x1" | H29: 30 | I29: 2940 | J29: 2940 | K29: =(60*3.1415/59)*(J29) -> 9392.5525 | L29: 244.25 | M29: 290.75 | N29: COMPLETED | O29: 0.0853 | P29: 0.1016
A30: 13 | B30: 2025Q-10-107JT | E30: Ø72"x1" | H30: 108 | I30: 14004.36 | J30: 14004.36 | K30: =(72*3.1415/59)*(J30) -> 53688.444 | L30: 477.38 | M30: 751.88 | N30: COMPLETED | O30: 0.0292 | P30: 0.0459
A31: 14 | B31: 2025Q-12-113SN | E31: Ø66"x.75" | H31: 25 | I31: 3125 | J31: 3125 | K31: =(66*3.1415/59)*(J31) -> 10981.939 | L31: 52.99 | M31: 90.49 | N31: COMPLETED | O31: 0.0158 | P31: 0.027
A32: 15 | B32: 2026Q-05-126TS | E32: Ø42"x1" | H32: 8 | I32: 480 | J32: 480 | K32: =(42*3.1415/59)*(J32) -> 1073.4346 | L32: 12.42 | M32: 16.92 | N32: COMPLETED | O32: 0.038 | P32: 0.0517
A33: 16 | B33: 2025Q-05-93 (HDD) | E33: Ø36"x.75" | H33: 14 | I33: 1624 | J33: 1624 | K33: =(36*3.1415/59)*(J33) -> 3112.9603 | L33: 20.7 | M33: 26.7 | N33: COMPLETED | O33: 0.0218 | P33: 0.0281
A34: 17 | B34: 2025Q-10-105 | E34: Ø36"x.75" | H34: 89 | I34: 5843 | J34: 5843 | K34: =(36*3.1415/59)*(J34) -> 11200.14 | L34: 72.38 | M34: 108.38 | N34: COMPLETED | O34: 0.0212 | P34: 0.0317
A35: 18 | B35: 2026Q-06-131TS | E35: Ø42"x1" | H35: 72 | I35: 4120 | J35: 1150 | K35: =(42*3.1415/59)*(J35) -> 2571.7703 | L35: 11.68 | M35: 20.68 | N35: IN PROGRESS | O35: 0.0149 | P35: 0.0264
A36: 19 | B36: 2026Q-01-116SN | E36: Ø42"x1" | H36: 48 | I36: 6279.84 | J36: 6279.84 | K36: =(42*3.1415/59)*(J36) -> 14043.745 | L36: 94.3 | M36: 166.3 | N36: IN PROGRESS | O36: 0.022 | P36: 0.0389
A37: 20 | B37: 2026Q-01-116SN | E37: Ø36"x1" | H37: 54 | I37: 6529.45 | J37: 6529.45 | K37: =(36*3.1415/59)*(J37) -> 12515.96 | L37: 87.98 | M37: 152.48 | N37: IN PROGRESS | O37: 0.0231 | P37: 0.04
A38: 21 | B38: 2026Q-11-111JT | E38: Ø78"x0.5" | H38: 3 | I38: 135 | J38: 90 | K38: =(78*3.1415/59)*(J38) -> 373.78525 | L38: 0.86 | M38: 2.36 | N38: IN PROGRESS | O38: 0.0076 | P38: 0.0207
A39: 23 | B39: 2026Q-10-108JT | E39: Ø96"x0.625" | H39: 4 | I39: 175 | J39: 135 | K39: =(96*3.1415/59)*(J39) -> 690.06508 | L39: 3.94 | M39: 6.94 | N39: IN PROGRESS | O39: 0.0187 | P39: 0.033
A40: 24 | B40: 2026Q-02-123JE | E40: Ø42"x1" | H40: 120 | I40: 10540 | J40: 10377 | K40: =(42*3.1415/59)*(J40) -> 23206.314 | L40: 89.84 | M40: 202.34 | N40: IN PROGRESS | O40: 0.0127 | P40: 0.0286
A41: 25 | B41: 2026Q-01-118KH | E41: Ø36"x0.625" | H41: 676 | I41: 44598.5 | J41: 6234 | K41: =(36*3.1415/59)*(J41) -> 11949.627 | L41: 24.54 | M41: 45.54 | N41: IN PROGRESS | O41: 0.0067 | P41: 0.0125
...

Sheet 05-095 (2.)
A2: Repair Rate : | C2: =B7/((72*3.1415/59)*(50/3.281)) -> 0.024339871 | F2: Repair Rate : | H2: =G7/((72*3.1415/59)*(50/3.281)) -> 0.0095510887 | K2: Repair Rate : | M2: =L7/((72*3.1415/59)*(50/3.281)) -> 1.7116646e-06 | P2: Repair Rate : | R2: =Q7/((72*3.1415/59)*(50/3.281)) -> 0.023466922 | U2: Repair Rate : | W2: =V7/((72*3.1415/59)*(50/3.281)) -> 0.023039006 | Z2: Repair Rate : | AB2: =AA7/((72*3.1415/59)*(50/3.281)) -> 0.01694548 | AE2: Repair Rate : | AG2: =AF7/((72*3.1415/59)*(50/3.281)) -> 0.0421583 | AJ2: Repair Rate : | AL2: =AK7/((72*3.1415/59)*(50/3.281)) -> 0.030433397 | AO2: Repair Rate : | AQ2: =AP7/((72*3.1415/59)*(50/3.281)) -> 0.032607211 | AT2: Repair Rate : | AV2: =AU7/((72*3.1415/59)*(50/3.281)) -> 0.028259583 | AY2: Repair Rate : | BA2: =AZ7/((72*3.1415/59)*(50/3.281)) -> 0.035653974 | BD2: Repair Rate : | BF2: =BE7/((72*3.1415/59)*(50/3.281)) -> 0.10259718 | BI2: Repair Rate : | BK2: =BJ7/((72*3.1415/59)*(50/3.281)) -> 0.090427243 | BN2: Repair Rate : | BP2: =BO7/((72*3.1415/59)*(50/3.281)) -> 0.020420159
A6: 50 ft | B6: 105 | F6: 50 ft | G6: 107 | K6: 50 ft | L6: 109 | P6: 50 ft | Q6: 111 | U6: 50 ft | V6: 113 | Z6: 50 ft | AA6: 115 | AE6: 50 ft | AF6: 117 | AJ6: 50 ft | AK6: 119 | AO6: 50 ft | AP6: 122 | AT6: 50 ft | AU6: 123 | AY6: 50 ft | AZ6: 124 | BD6: 50 ft | BE6: 125 | BI6: 50 ft | BJ6: 126 | BN6: 50 ft | BO6: 127
B7: 1.422 | C7: m. | D7: 1 | E7: B.E | G7: 0.558 | H7: m. | I7: 1 | J7: B.E | L7: 0.0001 | M7: m. | N7: 1 | O7: B.E | Q7: 1.371 | R7: m. | T7: B.E | V7: 1.346 | W7: m. | X7: 1 | Y7: B.E | AA7: 0.99 | AB7: m. | AC7: 1 | AD7: B.E | AF7: 2.463 | AG7: m. | AH7: 1 | AI7: B.E | AK7: 1.778 | AL7: m. | AN7: B.E | AP7: 1.905 | AQ7: m. | AR7: 1 | AS7: B.E | AU7: 1.651 | AV7: m. | AW7: 1 | AX7: B.E | AZ7: 2.083 | BA7: m. | BB7: 1 | BC7: B.E | BE7: 5.994 | BF7: m. | BH7: B.E | BJ7: 5.283 | BK7: m. | BL7: 1 | BM7: B.E | BO7: 1.193 | BP7: m. | BQ7: 1 | BR7: B.E
A8: Repair Rate : | C8: =B13/((72*3.1415/59)*(50/3.281)) -> 1.7116646e-07 | F8: Repair Rate : | H8: =G13/((72*3.1415/59)*(50/3.281)) -> 0.064735156 | K8: Repair Rate : | M8: =L13/((72*3.1415/59)*(50/3.281)) -> 0.059788446 | P8: Repair Rate : | R8: =Q13/((72*3.1415/59)*(50/3.281)) -> 0.034781025 | U8: Repair Rate : | W8: =V13/((72*3.1415/59)*(50/3.281)) -> 0.042603333 | Z8: Repair Rate : | AB8: =AA13/((72*3.1415/59)*(50/3.281)) -> 0.026513685 | AE8: Repair Rate : | AG8: =AF13/((72*3.1415/59)*(50/3.281)) -> 0.030861313 | AJ8: Repair Rate : | AL8: =AK13/((72*3.1415/59)*(50/3.281)) -> 1.7116646e-06 | AO8: Repair Rate : | AQ8: =AP13/((72*3.1415/59)*(50/3.281)) -> 0.043031249 | AT8: Repair Rate : | AV8: =AU13/((72*3.1415/59)*(50/3.281)) -> 0.0026017302 | AY8: Repair Rate : | BA8: =AZ13/((72*3.1415/59)*(50/3.281)) -> 0.0039025954 | BD8: Repair Rate : | BF8: =BE13/((72*3.1415/59)*(50/3.281)) -> 1.7116646e-06 | BI8: Repair Rate : | BK8: =BJ13/((72*3.1415/59)*(50/3.281)) -> 0.061294711 | BN8: Repair Rate : | BP8: =BO13/((72*3.1415/59)*(50/3.281)) -> 0.015216699
A12: 50 ft | B12: 128 | F12: 50 ft | G12: 129 | K12: 50 ft | L12: 131 | P12: 50 ft | Q12: 132 | U12: 50 ft | V12: 134 | Z12: 50 ft | AA12: 135 | AE12: 50 ft | AF12: 136 | AJ12: 50 ft | AK12: 137 | AO12: 50 ft | AP12: 138 | AT12: 50 ft | AU12: 139 | AY12: 50 ft | AZ12: 140 | BD12: 50 ft | BE12: 142 | BI12: 50 ft | BJ12: 143 | BN12: 50 ft | BO12: 145
B13: 1e-05 | C13: m. | E13: B.E | G13: 3.782 | H13: m. | I13: 1 | J13: B.E | L13: 3.493 | M13: m. | N13: 1 | O13: B.E | Q13: 2.032 | R13: m. | S13: 1 | T13: B.E | V13: 2.489 | W13: m. | X13: 1 | Y13: B.E | AA13: 1.549 | AB13: m. | AC13: 1 | AD13: B.E | AF13: 1.803 | AG13: m. | AI13: B.E | AK13: 0.0001 | AL13: m. | AM13: 1 | AN13: B.E | AP13: 2.514 | AQ13: m. | AR13: 1 | AS13: B.E | AU13: 0.152 | AV13: m. | AX13: B.E | AZ13: 0.228 | BA13: m. | BB13: 1 | BC13: B.E | BE13: 0.0001 | BF13: m. | BG13: 1 | BH13: B.E | BJ13: 3.581 | BK13: m. | BL13: 1 | BM13: B.E | BO13: 0.889 | BP13: m. | BQ13: 1 | BR13: B.E
A14: Repair Rate : | C14: =B19/((72*3.1415/59)*(50/3.281)) -> 0.051726505 | F14: Repair Rate : | H14: =G19/((72*3.1415/59)*(50/3.281)) -> 0.022166057 | K14: Repair Rate : | M14: =L19/((72*3.1415/59)*(50/3.281)) -> 0.07303673 | P14: Repair Rate : | R14: =Q19/((72*3.1415/59)*(50/3.281)) -> 1.7116646e-06 | U14: Repair Rate : | W14: =V19/((72*3.1415/59)*(50/3.281)) -> 0.093474006 | Z14: Repair Rate : | AB14: =AA19/((72*3.1415/59)*(50/3.281)) -> 0.016072531 | AE14: Repair Rate : | AG14: =AF19/((72*3.1415/59)*(50/3.281)) -> 0.10259718 | AJ14: Repair Rate : | AL14: =AK19/((72*3.1415/59)*(50/3.281)) -> 0.063896441 | AO14: Repair Rate : | AQ14: =AP19/((72*3.1415/59)*(50/3.281)) -> 0.046950961 | AT14: Repair Rate : | AV14: =AU19/((72*3.1415/59)*(50/3.281)) -> 0.017390513 | AY14: Repair Rate : | BA14: =AZ19/((72*3.1415/59)*(50/3.281)) -> 0.0017287813 | BD14: Repair Rate : | BF14: =BE19/((72*3.1415/59)*(50/3.281)) -> 1.7116646e-06 | BI14: Repair Rate : | BK14: =BJ19/((72*3.1415/59)*(50/3.281)) -> 0.19607118 | BN14: Repair Rate : | BP14: =BO19/((72*3.1415/59)*(50/3.281)) -> 0.031289229
A18: 50 ft | B18: 146 | F18: 50 ft | G18: 147 | K18: 50 ft | L18: 148 | P18: 50 ft | Q18: 150 | U18: 50 ft | V18: 151 | Z18: 50 ft | AA18: 152 | AE18: 50 ft | AF18: 153 | AJ18: 50 ft | AK18: 154 | AO18: 50 ft | AP18: 155 | AT18: 50 ft | AU18: 156 | AY18: 50 ft | AZ18: 157 | BD18: 50 ft | BE18: 158 | BI18: 50 ft | BJ18: 159 | BN18: 50 ft | BO18: 161
B19: 3.022 | C19: m. | D19: 1 | E19: B.E | G19: 1.295 | H19: m. | J19: B.E | L19: 4.267 | M19: m. | N19: 1 | O19: B.E | Q19: 0.0001 | R19: m. | S19: 1 | T19: B.E | V19: 5.461 | W19: m. | X19: 1 | Y19: B.E | AA19: 0.939 | AB19: m. | AD19: B.E | AF19: 5.994 | AG19: m. | AH19: 1 | AI19: B.E | AK19: 3.733 | AL19: m. | AM19: 1 | AN19: B.E | AP19: 2.743 | AQ19: m. | AS19: B.E | AU19: 1.016 | AV19: m. | AW19: 1 | AX19: B.E | AZ19: 0.101 | BA19: m. | BB19: 1 | BC19: B.E | BE19: 0.0001 | BF19: m. | BH19: B.E | BJ19: 11.455 | BK19: m. | BL19: 1 | BM19: B.E | BO19: 1.828 | BP19: m. | BQ19: 1 | BR19: B.E
A20: Repair Rate : | C20: =B25/((72*3.1415/59)*(50/3.281)) -> 0.13352696 | F20: Repair Rate : | H20: =G25/((72*3.1415/59)*(50/3.281)) -> 0.043904198 | K20: Repair Rate : | M20: =L25/((72*3.1415/59)*(50/3.281)) -> 0.0034746792 | P20: Repair Rate : | R20: =Q25/((72*3.1415/59)*(50/3.281)) -> 0.017818429 | U20: Repair Rate : | W20: =V25/((72*3.1415/59)*(50/3.281)) -> 0.016072531 | Z20: Repair Rate : | AB20: =AA25/((72*3.1415/59)*(50/3.281)) -> 0.30955113 | AE20: Repair Rate : | AG20: =AF25/((72*3.1415/59)*(50/3.281)) -> 0.26955295 | AJ20: Repair Rate : | AL20: =AK25/((72*3.1415/59)*(50/3.281)) -> 0.070417883 | AO20: Repair Rate : | AQ20: =AP25/((72*3.1415/59)*(50/3.281)) -> 0.012169936 | AT20: Repair Rate : | AV20: =AU25/((72*3.1415/59)*(50/3.281)) -> 0.044332114 | AY20: Repair Rate : | BA20: =AZ25/((72*3.1415/59)*(50/3.281)) -> 0.20606731 | BD20: Repair Rate : | BF20: =BE25/((72*3.1415/59)*(50/3.281)) -> 0.0095510887 | BI20: Repair Rate : | BK20: =BJ25/((72*3.1415/59)*(50/3.281)) -> 0.10607186 | BN20: Repair Rate : | BP20: =BO25/((72*3.1415/59)*(50/3.281)) -> 0.067816153
A24: 50 ft | B24: 162 | F24: 50 ft | G24: 163 | K24: 50 ft | L24: 164 | P24: 50 ft | Q24: 165 | U24: 50 ft | V24: 166 | Z24: 50 ft | AA24: 167 | AE24: 50 ft | AF24: 168 | AJ24: 50 ft | AK24: 169 | AO24: 50 ft | AP24: 170 | AT24: 50 ft | AU24: 171 | AY24: 50 ft | AZ24: 172 | BD24: 50 ft | BE24: 173 | BI24: 50 ft | BJ24: 174 | BN24: 50 ft | BO24: 175
B25: 7.801 | C25: m. | D25: 1 | E25: B.E | G25: 2.565 | H25: m. | J25: B.E | L25: 0.203 | M25: m. | N25: 1 | O25: B.E | Q25: 1.041 | R25: m. | S25: 1 | T25: B.E | V25: 0.939 | W25: m. | Y25: B.E | AA25: 18.0848 | AB25: m. | AD25: B.E | AF25: 15.748 | AG25: m. | AH25: 1 | AI25: B.E | AK25: 4.114 | AL25: m. | AM25: 1 | AN25: B.E | AP25: 0.711 | AQ25: m. | AS25: B.E | AU25: 2.59 | AV25: m. | AW25: 1 | AX25: B.E | AZ25: 12.039 | BA25: m. | BC25: B.E | BE25: 0.558 | BF25: m. | BG25: 1 | BH25: B.E | BJ25: 6.197 | BK25: m. | BL25: 1 | BM25: B.E | BO25: 3.962 | BP25: m. | BR25: B.E
A26: Repair Rate : | C26: =B31/((72*3.1415/59)*(50/3.281)) -> 0.057374998 | F26: Repair Rate : | H26: =G31/((72*3.1415/59)*(50/3.281)) -> 0.1086907 | K26: Repair Rate : | M26: =L31/((72*3.1415/59)*(50/3.281)) -> 0.0069493584 | P26: Repair Rate : | R26: =Q31/((72*3.1415/59)*(50/3.281)) -> 0.031289229 | U26: Repair Rate : | W26: =V31/((72*3.1415/59)*(50/3.281)) -> 0.0078223074 | Z26: Repair Rate : | AB26: =AA31/((72*3.1415/59)*(50/3.281)) -> 1.7116646e-14 | AE26: Repair Rate : | AG26: =AF31/((72*3.1415/59)*(50/3.281)) -> 0.17910859 | AJ26: Repair Rate : | AL26: =AK31/((72*3.1415/59)*(50/3.281)) -> 1.7116646e-06 | AO26: Repair Rate : | AQ26: =AP31/((72*3.1415/59)*(50/3.281)) -> 0.039984486 | AT26: Repair Rate : | AV26: =AU31/((72*3.1415/59)*(50/3.281)) -> 0.10954654 | AY26: Repair Rate : | BA26: =AZ31/((72*3.1415/59)*(50/3.281)) -> 0.05042564 | BD26: Repair Rate : | BF26: =BE31/((72*3.1415/59)*(50/3.281)) -> 0.030433397 | BI26: Repair Rate : | BK26: =BJ31/((72*3.1415/59)*(50/3.281)) -> 0.010424038 | BN26: Repair Rate : | BP26: =BO31/((72*3.1415/59)*(50/3.281)) -> 0.013898717
A30: 50 ft | B30: 176 | F30: 50 ft | G30: 177 | K30: 50 ft | L30: 178 | P30: 50 ft | Q30: 179 | U30: 50 ft | V30: 180 | Z30: 50 ft | AA30: 181 | AE30: 50 ft | AF30: 182 | AJ30: 50 ft | AK30: 184 | AO30: 50 ft | AP30: 185 | AT30: 50 ft | AU30: 186 | AY30: 50 ft | AZ30: 187 | BD30: 50 ft | BE30: 188 | BI30: 50 ft | BJ30: 189 | BN30: 50 ft | BO30: 190
B31: 3.352 | C31: m. | D31: 1 | E31: B.E | G31: 6.35 | H31: m. | I31: 1 | J31: B.E | L31: 0.406 | M31: m. | O31: B.E | Q31: 1.828 | R31: m. | S31: 1 | T31: B.E | V31: 0.457 | W31: m. | X31: 1 | Y31: B.E | AA31: 1e-12 | AB31: m. | AD31: B.E | AF31: 10.464 | AG31: m. | AH31: 1 | AI31: B.E | AK31: 0.0001 | AL31: m. | AM31: 1 | AN31: B.E | AP31: 2.336 | AQ31: m. | AR31: 1 | AS31: B.E | AU31: 6.4 | AV31: m. | AX31: B.E | AZ31: 2.946 | BA31: m. | BB31: 1 | BC31: B.E | BE31: 1.778 | BF31: m. | BG31: 1 | BH31: B.E | BJ31: 0.609 | BK31: m. | BM31: B.E | BO31: 0.812 | BP31: m. | BQ31: 1 | BR31: B.E
A32: Repair Rate : | C32: =B37/((72*3.1415/59)*(50/3.281)) -> 0.014771666 | F32: Repair Rate : | H32: =G37/((72*3.1415/59)*(50/3.281)) -> 0.0073772746 | K32: Repair Rate : | M32: =L37/((72*3.1415/59)*(50/3.281)) -> 0.030861313 | P32: Repair Rate : | R32: =Q37/((72*3.1415/59)*(50/3.281)) -> 0.088691615 | U32: Repair Rate : | W32: =V37/((72*3.1415/59)*(50/3.281)) -> 0.012597852 | Z32: Repair Rate : | AB32: =AA37/((72*3.1415/59)*(50/3.281)) -> 0.13825115 | AE32: Repair Rate : | AG32: =AF37/((72*3.1415/59)*(50/3.281)) -> 0.094774871 | AJ32: Repair Rate : | AL32: =AK37/((72*3.1415/59)*(50/3.281)) -> 0.068689102 | AO32: Repair Rate : | AQ32: =AP37/((72*3.1415/59)*(50/3.281)) -> 0.019564327 | AT32: Repair Rate : | AV32: =AU37/((72*3.1415/59)*(50/3.281)) -> 0.013042885 | AY32: Repair Rate : | BA32: =AZ37/((72*3.1415/59)*(50/3.281)) -> 0.098677466 | BD32: Repair Rate : | BF32: =BE37/((72*3.1415/59)*(50/3.281)) -> 0.092601057 | BI32: Repair Rate : | BK32: =BJ37/((72*3.1415/59)*(50/3.281)) -> 0.010424038 | BN32: Repair Rate : | BP32: =BO37/((72*3.1415/59)*(50/3.281)) -> 0.052171538
A36: 50 ft | B36: 191 | F36: 50 ft | G36: 192 | K36: 50 ft | L36: 193 | P36: 50 ft | Q36: 194 | U36: 50 ft | V36: 195 | Z36: 50 ft | AA36: 196 | AE36: 50 ft | AF36: 198 | AJ36: 50 ft | AK36: 199 | AO36: 50 ft | AP36: 200 | AT36: 50 ft | AU36: 201 | AY36: 50 ft | AZ36: 202 | BD36: 50 ft | BE36: 203 | BI36: 50 ft | BJ36: 204 | BN36: 50 ft | BO36: 205
B37: 0.863 | C37: m. | D37: 1 | E37: B.E | G37: 0.431 | H37: m. | J37: B.E | L37: 1.803 | M37: m. | N37: 1 | O37: B.E | Q37: 5.1816 | R37: m. | S37: 1 | T37: B.E | V37: 0.736 | W37: m. | Y37: B.E | AA37: 8.077 | AB37: m. | AC37: 1 | AD37: B.E | AF37: 5.537 | AG37: m. | AH37: 1 | AI37: B.E | AK37: 4.013 | AL37: m. | AM37: 1 | AN37: B.E | AP37: 1.143 | AQ37: m. | AS37: B.E | AU37: 0.762 | AV37: m. | AW37: 1 | AX37: B.E | AZ37: 5.765 | BA37: m. | BB37: 1 | BC37: B.E | BE37: 5.41 | BF37: m. | BH37: B.E | BJ37: 0.609 | BK37: m. | BL37: 1 | BM37: B.E | BO37: 3.048 | BP37: m. | BQ37: 1 | BR37: B.E
A38: Repair Rate : | C38: =B43/((72*3.1415/59)*(50/3.281)) -> 0.074337595 | F38: Repair Rate : | H38: =G43/((72*3.1415/59)*(50/3.281)) -> 0.010424038 | K38: Repair Rate : | M38: =L43/((72*3.1415/59)*(50/3.281)) -> 0.032162178 | P38: Repair Rate : | R38: =Q43/((72*3.1415/59)*(50/3.281)) -> 0.056084403 | U38: Repair Rate : | W38: =V43/((72*3.1415/59)*(50/3.281)) -> 0.020433852 | Z38: Repair Rate : | AB38: =AA43/((72*3.1415/59)*(50/3.281)) -> 0.070417883 | AE38: Repair Rate : | AG38: =AF43/((72*3.1415/59)*(50/3.281)) -> 0.039128654 | AJ38: Repair Rate : | AL38: =AK43/((72*3.1415/59)*(50/3.281)) -> 0.022172904 | AO38: Repair Rate : | AQ38: =AP43/((72*3.1415/59)*(50/3.281)) -> 0.026085769 | AT38: Repair Rate : | AV38: =AU43/((72*3.1415/59)*(50/3.281)) -> 0.031737686 | AY38: Repair Rate : | BA38: =AZ43/((72*3.1415/59)*(50/3.281)) -> 0.041730384 | BD38: Repair Rate : | BF38: =BE43/((72*3.1415/59)*(50/3.281)) -> 0.043476282 | BI38: Repair Rate : | BK38: =BJ43/((72*3.1415/59)*(50/3.281)) -> 0.0069562051 | BN38: Repair Rate : | BP38: =BO43/((72*3.1415/59)*(50/3.281)) -> 0.03086816
A42: 50 ft | B42: 223 | F42: 50 ft | G42: 224 | K42: 50 ft | L42: 226 | P42: 50 ft | Q42: 247 | U42: 50 ft | V42: 248 | Z42: 50 ft | AA42: 249 | AE42: 50 ft | AF42: 250 | AJ42: 50 ft | AK42: 251 | AO42: 50 ft | AP42: 252 | AT42: 50 ft | AU42: 253 | AY42: 50 ft | AZ42: 254 | BD42: 50 ft | BE42: 255 | BI42: 50 ft | BJ42: 256 | BN42: 50 ft | BO42: 258
B43: 4.343 | C43: m. | E43: B.E | G43: 0.609 | H43: m. | J43: B.E | L43: 1.879 | M43: m. | N43: 1 | O43: B.E | Q43: 3.2766 | R43: m. | T43: B.E | V43: 1.1938 | W43: m. | X43: 1 | Y43: B.E | AA43: 4.114 | AB43: m. | AC43: 1 | AD43: B.E | AF43: 2.286 | AG43: m. | AI43: B.E | AK43: 1.2954 | AL43: m. | AM43: 1 | AN43: B.E | AP43: 1.524 | AQ43: m. | AR43: 1 | AS43: B.E | AU43: 1.8542 | AV43: m. | AX43: B.E | AZ43: 2.438 | BA43: m. | BB43: 1 | BC43: B.E | BE43: 2.54 | BF43: m. | BG43: 1 | BH43: B.E | BJ43: 0.4064 | BK43: m. | BM43: B.E | BO43: 1.8034 | BP43: m. | BQ43: 1 | BR43: B.E
A44: Repair Rate : | C44: =B49/((72*3.1415/59)*(50/3.281)) -> 0.0052171538 | F44: Repair Rate : | H44: =G49/((72*3.1415/59)*(50/3.281)) -> 0.0052171538 | K44: Repair Rate : | M44: =L49/((72*3.1415/59)*(50/3.281)) -> 0.029563872 | P44: Repair Rate : | R44: =Q49/((72*3.1415/59)*(50/3.281)) -> 1.7116646e-11 | U44: Repair Rate : | W44: =V49/((72*3.1415/59)*(50/3.281)) -> 0.15564509 | Z44: Repair Rate : | AB44: =AA49/((72*3.1415/59)*(50/3.281)) -> 0.068244069 | AE44: Repair Rate : | AG44: =AF49/((72*3.1415/59)*(50/3.281)) -> 0.049562961 | AJ44: Repair Rate : | AL44: =AK49/((72*3.1415/59)*(50/3.281)) -> 0.06477966 | AO44: Repair Rate : | AQ44: =AP49/((72*3.1415/59)*(50/3.281)) -> 0.047378877 | AT44: Repair Rate : | AV44: =AU49/((72*3.1415/59)*(50/3.281)) -> 0.016086224 | AY44: Repair Rate : | BA44: =AZ49/((72*3.1415/59)*(50/3.281)) -> 0.040857435 | BD44: Repair Rate : | BF44: =BE49/((72*3.1415/59)*(50/3.281)) -> 0.23997538 | BI44: Repair Rate : | BK44: =BJ49/((72*3.1415/59)*(50/3.281)) -> 0.0065214423 | BN44: Repair Rate : | BP44: =BO49/((72*3.1415/59)*(50/3.281)) -> 0.085648275
A48: 50 ft | B48: 264 | F48: 50 ft | G48: 265 | K48: 50 ft | L48: 266 | P48: 50 ft | Q48: 268 | U48: 50 ft | V48: 269 | Z48: 50 ft | AA48: 270 | AE48: 50 ft | AF48: 271 | AJ48: 50 ft | AK48: 272 | AO48: 50 ft | AP48: 273 | AT48: 50 ft | AU48: 274 | AY48: 50 ft | AZ48: 275 | BD48: 50 ft | BE48: 276 | BI48: 50 ft | BJ48: 277 | BN48: 50 ft | BO48: 278
B49: 0.3048 | C49: m. | E49: B.E | G49: 0.3048 | H49: m. | I49: 1 | J49: B.E | L49: 1.7272 | M49: m. | N49: 1 | O49: B.E | Q49: 1e-09 | R49: m. | S49: 1 | T49: B.E | V49: 9.0932 | W49: m. | X49: 1 | Y49: B.E | AA49: 3.987 | AB49: m. | AC49: 1 | AD49: B.E | AF49: 2.8956 | AG49: m. | AI49: B.E | AK49: 3.7846 | AL49: m. | AM49: 1 | AN49: B.E | AP49: 2.768 | AQ49: m. | AR49: 1 | AS49: B.E | AU49: 0.9398 | AV49: m. | AX49: B.E | AZ49: 2.387 | BA49: m. | BB49: 1 | BC49: B.E | BE49: 14.02 | BF49: m. | BG49: 1 | BH49: B.E | BJ49: 0.381 | BK49: m. | BM49: B.E | BO49: 5.0038 | BP49: m. | BQ49: 1 | BR49: B.E
A63: Repair Rate : | C63: =B68/((72*3.1415/59)*(50/3.281)) -> 0.039128654 | F63: Repair Rate : | H63: =G68/((72*3.1415/59)*(50/3.281)) -> 0.019564327 | K63: Repair Rate : | M63: =L68/((72*3.1415/59)*(50/3.281)) -> 0.060432032 | P63: Repair Rate : | R63: =Q68/((72*3.1415/59)*(50/3.281)) -> 0.045650096 | U63: Repair Rate : | W63: =V68/((72*3.1415/59)*(50/3.281)) -> 0.020865192 | Z63: Repair Rate : | AB63: =AA68/((72*3.1415/59)*(50/3.281)) -> 0.028687499 | AE63: Repair Rate : | AG63: =AF68/((72*3.1415/59)*(50/3.281)) -> 0.02782482 | AJ63: Repair Rate : | AL63: =AK68/((72*3.1415/59)*(50/3.281)) -> 0.02521282 | AO63: Repair Rate : | AQ63: =AP68/((72*3.1415/59)*(50/3.281)) -> 0.056074133 | AT63: Repair Rate : | AV63: =AU68/((72*3.1415/59)*(50/3.281)) -> 0.037810672 | AY63: Repair Rate : | BA63: =AZ68/((72*3.1415/59)*(50/3.281)) -> 0.042603333 | BD63: Repair Rate : | BF63: =BE68/((72*3.1415/59)*(50/3.281)) -> 0.0339115 | BI63: Repair Rate : | BK63: =BJ68/((72*3.1415/59)*(50/3.281)) -> 0.011724903 | BN63: Repair Rate : | BP63: =BO68/((72*3.1415/59)*(50/3.281)) -> 0.053910589
A67: 50 ft | B67: 279 | F67: 50 ft | G67: 280 | K67: 50 ft | L67: 281 | P67: 50 ft | Q67: 282 | U67: 50 ft | V67: 283 | Z67: 50 ft | AA67: 284 | AE67: 50 ft | AF67: 285 | AJ67: 50 ft | AK67: 286 | AO67: 50 ft | AP67: 287 | AT67: 50 ft | AU67: 288 | AY67: 50 ft | AZ67: 289 | BD67: 50 ft | BE67: 290 | BI67: 50 ft | BJ67: 291 | BN67: 50 ft | BO67: 292
B68: 2.286 | C68: m. | D68: 1 | E68: B.E | G68: 1.143 | H68: m. | J68: B.E | L68: 3.5306 | M68: m. | N68: 1 | O68: B.E | Q68: 2.667 | R68: m. | S68: 1 | T68: B.E | V68: 1.219 | W68: m. | Y68: B.E | AA68: 1.676 | AB68: m. | AC68: 1 | AD68: B.E | AF68: 1.6256 | AG68: m. | AH68: 1 | AI68: B.E | AK68: 1.473 | AL68: m. | AN68: B.E | AP68: 3.276 | AQ68: m. | AR68: 1 | AS68: B.E | AU68: 2.209 | AV68: m. | AW68: 1 | AX68: B.E | AZ68: 2.489 | BA68: m. | BC68: B.E | BE68: 1.9812 | BF68: m. | BG68: 1 | BH68: B.E | BJ68: 0.685 | BK68: m. | BL68: 1 | BM68: B.E | BO68: 3.1496 | BP68: m. | BR68: B.E
A69: Repair Rate : | C69: =B74/((72*3.1415/59)*(45/3.281)) -> 0.038151103 | F69: Repair Rate : | H69: =G74/((72*3.1415/59)*(45/3.281)) -> 0.03767564 | K69: Repair Rate : | M69: =L74/((72*3.1415/59)*(45/3.281)) -> 1.9018496e-07 | P69: Repair Rate : | R69: =Q74/((72*3.1415/59)*(45/3.281)) -> 1.9018496e-06 | U69: Repair Rate : | W69: =V74/((72*3.1415/59)*(45/3.281)) -> 0.05652297 | Z69: Repair Rate : | AB69: =AA74/((72*3.1415/59)*(45/3.281)) -> 0.030905056 | AE69: Repair Rate : | AG69: =AF74/((72*3.1415/59)*(45/3.281)) -> 0.0081969717 | AJ69: Repair Rate : | AL69: =AK74/((72*3.1415/59)*(45/3.281)) -> 0.042011857 | AO69: Repair Rate : | AQ69: =AP74/((72*3.1415/59)*(45/3.281)) -> 0.068580696 | AT69: Repair Rate : | AV69: =AU74/((72*3.1415/59)*(45/3.281)) -> 0.029935113 | AY69: Repair Rate : | BA69: =AZ74/((72*3.1415/59)*(45/3.281)) -> 1.9018496e-07 | BD69: Repair Rate : | BF69: =BE74/((72*3.1415/59)*(45/3.281)) -> 0.072460469 | BI69: Repair Rate : | BK69: =BJ74/((72*3.1415/59)*(45/3.281)) -> 0.09218265 | BN69: Repair Rate : | BP69: =BO74/((72*3.1415/59)*(45/3.281)) -> 1.9018496e-05
A73: 45 ft | B73: 103 | F73: 45 ft | G73: 104 | K73: 45 ft | L73: 106 | P73: 45 ft | Q73: 108 | U73: 45 ft | V73: 110 | Z73: 45 ft | AA73: 112 | AE73: 45 ft | AF73: 114 | AJ73: 45 ft | AK73: 116 | AO73: 45 ft | AP73: 118 | AT73: 45 ft | AU73: 120 | AY73: 45 ft | AZ73: 121 | BD73: 45 ft | BE73: 130 | BI73: 45 ft | BJ73: 133 | BN73: 45 ft | BO73: 141
B74: 2.006 | C74: m. | E74: B.E | G74: 1.981 | H74: m. | I74: 1 | J74: B.E | L74: 1e-05 | M74: m. | O74: B.E | Q74: 0.0001 | R74: m. | T74: B.E | V74: 2.972 | W74: m. | X74: 1 | Y74: B.E | AA74: 1.625 | AB74: m. | AC74: 1 | AD74: B.E | AF74: 0.431 | AG74: m. | AI74: B.E | AK74: 2.209 | AL74: m. | AN74: B.E | AP74: 3.606 | AQ74: m. | AR74: 1 | AS74: B.E | AU74: 1.574 | AV74: m. | AW74: 1 | AX74: B.E | AZ74: 1e-05 | BA74: m. | BC74: B.E | BE74: 3.81 | BF74: m. | BH74: B.E | BJ74: 4.847 | BK74: m. | BM74: B.E | BO74: 0.001 | BP74: m. | BR74: B.E
A75: Repair Rate : | C75: =B80/((72*3.1415/59)*(45/3.281)) -> 0.06182913 | F75: Repair Rate : | H75: =G80/((72*3.1415/59)*(45/3.281)) -> 0.002415349 | K75: Repair Rate : | M75: =L80/((72*3.1415/59)*(45/3.281)) -> 0.002415349 | P75: Repair Rate : | R75: =Q80/((72*3.1415/59)*(45/3.281)) -> 0.050722329 | U75: Repair Rate : | W75: =V80/((72*3.1415/59)*(45/3.281)) -> 0.035735754 | Z75: Repair Rate : | AB75: =AA80/((72*3.1415/59)*(45/3.281)) -> 0.01302767 | AE75: Repair Rate : | AG75: =AF80/((72*3.1415/59)*(45/3.281)) -> 0.053137678 | AJ75: Repair Rate : | AL75: =AK80/((72*3.1415/59)*(45/3.281)) -> 1.9018496e-12 | AO75: Repair Rate : | AQ75: =AP80/((72*3.1415/59)*(45/3.281)) -> 0.0159375 | AT75: Repair Rate : | AV75: =AU80/((72*3.1415/59)*(45/3.281)) -> 0.11201894 | AY75: Repair Rate : | BA75: =AZ80/((72*3.1415/59)*(45/3.281)) -> 0.025598896 | BD75: Repair Rate : | BF75: =BE80/((72*3.1415/59)*(45/3.281)) -> 0.019798254 | BI75: Repair Rate : | BK75: =BJ80/((72*3.1415/59)*(45/3.281)) -> 0.0081969717 | BN75: Repair Rate : | BP75: =BO80/((72*3.1415/59)*(45/3.281)) -> 0.028489707
A79: 45 ft | B79: 144 | F79: 45 ft | G79: 149 | K79: 45 ft | L79: 160 | P79: 45 ft | Q79: 183 | U79: 45 ft | V79: 197 | Z79: 45 ft | AA79: 206 | AE79: 45 ft | AF79: 207 | AJ79: 45 ft | AK79: 208 | AO79: 45 ft | AP79: 209 | AT79: 45 ft | AU79: 210 | AY79: 45 ft | AZ79: 211 | BD79: 45 ft | BE79: 212 | BI79: 45 ft | BJ79: 213 | BN79: 45 ft | BO79: 214
B80: 3.251 | C80: m. | E80: B.E | G80: 0.127 | H80: m. | J80: B.E | L80: 0.127 | M80: m. | O80: B.E | Q80: 2.667 | R80: m. | T80: B.E | V80: 1.879 | W80: m. | Y80: B.E | AA80: 0.685 | AB80: m. | AD80: B.E | AF80: 2.794 | AG80: m. | AH80: 1 | AI80: B.E | AK80: 1e-10 | AL80: m. | AN80: B.E | AP80: 0.838 | AQ80: m. | AR80: 1 | AS80: B.E | AU80: 5.89 | AV80: m. | AX80: B.E | AZ80: 1.346 | BA80: m. | BB80: 1 | BC80: B.E | BE80: 1.041 | BF80: m. | BG80: 1 | BH80: B.E | BJ80: 0.431 | BK80: m. | BM80: B.E | BO80: 1.498 | BP80: m. | BQ80: 1 | BR80: B.E
A81: Repair Rate : | C81: =B86/((72*3.1415/59)*(45/3.281)) -> 0.063274536 | F81: Repair Rate : | H81: =G86/((72*3.1415/59)*(45/3.281)) -> 0.017382905 | K81: Repair Rate : | M81: =L86/((72*3.1415/59)*(45/3.281)) -> 0.012552207 | P81: Repair Rate : | R81: =Q86/((72*3.1415/59)*(45/3.281)) -> 0.0057968376 | U81: Repair Rate : | W81: =V86/((72*3.1415/59)*(45/3.281)) -> 1.9018496e-15 | Z81: Repair Rate : | AB81: =AA86/((72*3.1415/59)*(45/3.281)) -> 0.012552207 | AE81: Repair Rate : | AG81: =AF86/((72*3.1415/59)*(45/3.281)) -> 0.065689885 | AJ81: Repair Rate : | AL81: =AK86/((72*3.1415/59)*(45/3.281)) -> 0.060383725 | AO81: Repair Rate : | AQ81: =AP86/((72*3.1415/59)*(45/3.281)) -> 0.025598896 | AT81: Repair Rate : | AV81: =AU86/((72*3.1415/59)*(45/3.281)) -> 0.061334649 | AY81: Repair Rate : | BA81: =AZ86/((72*3.1415/59)*(45/3.281)) -> 0.092258724 | BD81: Repair Rate : | BF81: =BE86/((72*3.1415/59)*(45/3.281)) -> 0.099512378 | BI81: Repair Rate : | BK81: =BJ86/((72*3.1415/59)*(45/3.281)) -> 0.013997613 | BN81: Repair Rate : | BP81: =BO86/((72*3.1415/59)*(45/3.281)) -> 0.0067629771
A85: 45 ft | B85: 215 | F85: 45 ft | G85: 216 | K85: 45 ft | L85: 217 | P85: 45 ft | Q85: 218 | U85: 45 ft | V85: 219 | Z85: 45 ft | AA85: 220 | AE85: 45 ft | AF85: 221 | AJ85: 45 ft | AK85: 222 | AO85: 45 ft | AP85: 225 | AT85: 45 ft | AU85: 227 | AY85: 45 ft | AZ85: 228 | BD85: 45 ft | BE85: 229 | BI85: 45 ft | BJ85: 230 | BN85: 45 ft | BO85: 231
B86: 3.327 | C86: m. | E86: B.E | G86: 0.914 | H86: m. | I86: 1 | J86: B.E | L86: 0.66 | M86: m. | N86: 1 | O86: B.E | Q86: 0.3048 | R86: m. | T86: B.E | V86: 1e-13 | W86: m. | X86: 1 | Y86: B.E | AA86: 0.66 | AB86: m. | AD86: B.E | AF86: 3.454 | AG86: m. | AH86: 1 | AI86: B.E | AK86: 3.175 | AL86: m. | AN86: B.E | AP86: 1.346 | AQ86: m. | AS86: B.E | AU86: 3.225 | AV86: m. | AX86: B.E | AZ86: 4.851 | BA86: m. | BB86: 1 | BC86: B.E | BE86: 5.2324 | BF86: m. | BH86: B.E | BJ86: 0.736 | BK86: m. | BL86: 1 | BM86: B.E | BO86: 0.3556 | BP86: m. | BQ86: 1 | BR86: B.E
A87: Repair Rate : | C87: =B92/((72*3.1415/59)*(45/3.281)) -> 0.0038607547 | F87: Repair Rate : | H87: =G92/((72*3.1415/59)*(45/3.281)) -> 0.066663632 | K87: Repair Rate : | M87: =L92/((72*3.1415/59)*(45/3.281)) -> 0.010627536 | P87: Repair Rate : | R87: =Q92/((72*3.1415/59)*(45/3.281)) -> 0.0086952563 | U87: Repair Rate : | W87: =V92/((72*3.1415/59)*(45/3.281)) -> 0.17196524 | Z87: Repair Rate : | AB87: =AA92/((72*3.1415/59)*(45/3.281)) -> 0.027051909 | AE87: Repair Rate : | AG87: =AF92/((72*3.1415/59)*(45/3.281)) -> 0.019322792 | AJ87: Repair Rate : | AL87: =AK92/((72*3.1415/59)*(45/3.281)) -> 1.9018496e-13 | AO87: Repair Rate : | AQ87: =AP92/((72*3.1415/59)*(45/3.281)) -> 0.034297956 | AT87: Repair Rate : | AV87: =AU92/((72*3.1415/59)*(45/3.281)) -> 0.022221211 | AY87: Repair Rate : | BA87: =AZ92/((72*3.1415/59)*(45/3.281)) -> 0.028018048 | BD87: Repair Rate : | BF87: =BE92/((72*3.1415/59)*(45/3.281)) -> 0.1135214 | BI87: Repair Rate : | BK87: =BJ92/((72*3.1415/59)*(45/3.281)) -> 0.11255526 | BN87: Repair Rate : | BP87: =BO92/((72*3.1415/59)*(45/3.281)) -> 0.085012677
A91: 45 ft | B91: 232 | F91: 45 ft | G91: 233 | K91: 45 ft | L91: 234 | P91: 45 ft | Q91: 235 | U91: 45 ft | V91: 236 | Z91: 45 ft | AA91: 237 | AE91: 45 ft | AF91: 238 | AJ91: 45 ft | AK91: 239 | AO91: 45 ft | AP91: 240 | AT91: 45 ft | AU91: 241 | AY91: 45 ft | AZ91: 242 | BD91: 45 ft | BE91: 243 | BI91: 45 ft | BJ91: 244 | BN91: 45 ft | BO91: 245
B92: 0.203 | C92: m. | E92: B.E | G92: 3.5052 | H92: m. | I92: 1 | J92: B.E | L92: 0.5588 | M92: m. | O92: B.E | Q92: 0.4572 | R92: m. | S92: 1 | T92: B.E | V92: 9.042 | W92: m. | X92: 1 | Y92: B.E | AA92: 1.4224 | AB92: m. | AD92: B.E | AF92: 1.016 | AG92: m. | AH92: 1 | AI92: B.E | AK92: 1e-11 | AL92: m. | AN92: B.E | AP92: 1.8034 | AQ92: m. | AR92: 1 | AS92: B.E | AU92: 1.1684 | AV92: m. | AW92: 1 | AX92: B.E | AZ92: 1.4732 | BA92: m. | BC92: B.E | BE92: 5.969 | BF92: m. | BH92: B.E | BJ92: 5.9182 | BK92: m. | BM92: B.E | BO92: 4.47 | BP92: m. | BQ92: 1 | BR92: B.E
A93: Repair Rate : | C93: =B98/((72*3.1415/59)*(45/3.281)) -> 0.079706516 | F93: Repair Rate : | H93: =G98/((72*3.1415/59)*(45/3.281)) -> 0.040094793 | K93: Repair Rate : | M93: =L98/((72*3.1415/59)*(45/3.281)) -> 0.028984188 | P93: Repair Rate : | R93: =Q98/((72*3.1415/59)*(45/3.281)) -> 0.016424373 | U93: Repair Rate : | W93: =V98/((72*3.1415/59)*(45/3.281)) -> 0.0086952563 | Z93: Repair Rate : | AB93: =AA98/((72*3.1415/59)*(45/3.281)) -> 1.9018496e-14 | AE93: Repair Rate : | AG93: =AF98/((72*3.1415/59)*(45/3.281)) -> 0.055553027 | AJ93: Repair Rate : | AL93: =AK98/((72*3.1415/59)*(45/3.281)) -> 1.9018496e-11
...

Sheet 01-117
A2: Repair Rate : | D2: =B7/((60*3.1415/50)*(80/3.281)) -> 0 | F2: Repair Rate : | I2: =G7/((60*3.1415/50)*(80/3.281)) -> 0 | K2: Repair Rate : | N2: =L7/((60*3.1415/50)*(80/3.281)) -> 0 | P2: Repair Rate : | S2: =Q7/((60*3.1415/50)*(80/3.281)) -> 0 | U2: Repair Rate : | X2: =V7/((60*3.1415/50)*(80/3.281)) -> 0 | Z2: Repair Rate : | AC2: =AA7/((60*3.1415/50)*(80/3.281)) -> 0 | AE2: Repair Rate : | AH2: =AF7/((60*3.1415/50)*(80/3.281)) -> 0 | AJ2: Repair Rate : | AM2: =AK7/((60*3.1415/50)*(80/3.281)) -> 0 | AO2: Repair Rate : | AR2: =AP7/((60*3.1415/64)*(82/3.281)) -> 0.043824955 | AT2: Repair Rate : | AW2: =AU7/((60*3.1415/64)*(82/3.281)) -> 0
A6: 80 feet | B6: 16 | F6: 80 feet | G6: 17 | K6: 80 feet | P6: 80 feet | U6: 80 feet | Z6: 80 feet | AE6: 80 feet | AJ6: 80 feet | AO6: 82 feet | AP6: 2 | AT6: 82 feet | AU6: 3
C7: m. | E7: B.E | H7: m. | J7: B.E | M7: m. | O7: B.E | R7: m. | T7: B.E | W7: m. | Y7: B.E | AB7: m. | AD7: B.E | AG7: m. | AI7: B.E | AL7: m. | AN7: B.E | AP7: 3.2258 | AQ7: m. | AR7: 4 | AS7: B.E | AV7: m. | AX7: B.E
A8: Repair Rate : | D8: =B13/((60*3.1415/64)*(82/3.281)) -> 0 | F8: Repair Rate : | I8: =G13/((60*3.1415/64)*(82/3.281)) -> 0 | K8: Repair Rate : | N8: =L13/((60*3.1415/64)*(82/3.281)) -> 0 | P8: Repair Rate : | S8: =Q13/((60*3.1415/64)*(82/3.281)) -> 0 | U8: Repair Rate : | X8: =V13/((60*3.1415/64)*(83/3.281)) -> 0.029998347 | Z8: Repair Rate : | AC8: =AA13/((60*3.1415/64)*(83/3.281)) -> 0 | AE8: Repair Rate : | AH8: =AF13/((60*3.1415/64)*(83/3.281)) -> 0.064093113 | AJ8: Repair Rate : | AM8: =AK13/((60*3.1415/64)*(83/3.281)) -> 0 | AO8: Repair Rate : | AR8: =AP13/((60*3.1415/64)*(83/3.281)) -> 0.0085230203 | AT8: Repair Rate : | AW8: =AU13/((60*3.1415/64)*(83/3.281)) -> 0
A12: 82 feet | B12: 4 | F12: 82 feet | G12: 5 | K12: 82 feet | L12: 6 | P12: 82 feet | Q12: 7 | U12: 83 feet | V12: 8 | Z12: 83 feet | AA12: 9 | AE12: 83 feet | AF12: 10 | AJ12: 83 feet | AK12: 11 | AO12: 83 feet | AP12: 12 | AT12: 83 feet | AU12: 13
C13: m. | E13: B.E | H13: m. | J13: B.E | M13: m. | O13: B.E | R13: m. | T13: B.E | V13: 2.235 | W13: m. | X13: 4 | Y13: B.E | AB13: m. | AD13: B.E | AF13: 4.7752 | AG13: m. | AH13: 4 | AI13: B.E | AL13: m. | AN13: B.E | AP13: 0.635 | AQ13: m. | AR13: 4 | AS13: B.E | AV13: m. | AX13: B.E
A14: Repair Rate : | D14: =B19/((60*3.1415/50)*(83/3.281)) -> 0 | F14: Repair Rate : | I14: =G19/((60*3.1415/64)*(84/3.281)) -> 0 | K14: Repair Rate : | N14: =L19/((60*3.1415/64)*(84/3.281)) -> 0
A18: 83 feet | B18: 15 | F18: 84 feet | G18: 1 | K18: 84 feet | L18: 14
C19: m. | E19: B.E | H19: m. | J19: B.E | M19: m. | O19: B.E
A20: Repair Rate : | D20: =B25/((42*3.1415/59)*(30/3.281)) -> 0
A21: Beveling
A24: 30 feet
C25: m. | E25: B.E
H38: {=SUM(COUNTIF(INDIRECT({"B6","G6","L6","Q6","V6","AA6","AF6","AK6","AP6","AU6","B12","G12","L12","Q12","V12","AA12","AF12","AK12","AP12","AU12","B18","G18","L18"}),">0"))} -> 17 | Q38: PREV. REPAIRED PIPE NO.S | X38: Total Repair Amount (Meter) | AC38: =B7+G7+L7+Q7+V7+AA7+AF7+AK7+AP7+AU7+AU13+AU19+AP19+AP13+AK13+AF13+AA13+V13+Q13+L13+G13+B13 -> 10.871 | AJ38: Total RepAIRED B.E. QTY. (Meter) | AO38: =D7+I7+N7+S7+X7+AC7+AH7+AM7+AR7+AW7+AW13+AW19+AR19+AR13+AM13+AH13+AC13+X13+S13+N13+I13+D13 -> 16 | AT38: B.E.
AO40: =AO38*1.5 -> 24 | AV40: meter
H41: {=SUM(COUNTIF(INDIRECT({"B7","G7","L7","Q7","V7","AA7","AF7","AK7","AP7","AU7","B13","G13","L13","Q13","V13","AA13","AF13","AK13","AP13","AU13","B19","G19","L19"}),">0"))} -> 4 | Q41: 10
X43: DAILY REPAIR AMOUNT (METER) | AC43: =AC38-AD51 -> 4.7752
AD51: 6.0958 | AL51: TOT. LENGTH (ft) | AO51: REP. PIPE TOT. LENGTH (ft) | AR51: TOT. REP. (mt) | AT51: TOT. REP. W/ B.E. (mt) | AY51: REP. RATIO (%)
AL54: 1881 | AO54: =AT82+AE81 -> 331 | AR54: =AC38 -> 10.871 | AT54: =AC38+AO40 -> 34.871 | AY54: (Total Tamir mt.)/[(Dx3.1415/W)(Total Length mt.)
AY56: =AR54/((60*3.1415/64)*(AT82/3.281))+((60*3.1415/50)*(AE81/3.281)) -> 0.036588061
AO58: =((60*3.1415/64)*(AT82))+((60*3.1415/50)*(AE81)) -> 974.84672
AY59: REP. RATIO W/ B.E. (%)
V60: 50 INCH WIDTH PLATE | Y60: 80 | AB60: 0 | AE60: =AB60*Y60 -> 0
AK61: 64 INCH WIDTH PLATE | AN61: 80 | AQ61: 0 | AT61: =AQ61*AN61 -> 0 | AY61: (Total Tamir w/B.E. mt.)/[(Dx3.1415/W)(Total Length mt.)
AN64: 82 | AQ64: 1 | AT64: =AQ64*AN64 -> 82
AY65: =AT54/((60*3.1415/64)*(AT82/3.281))+((60*3.1415/50)*(AE81/3.281)) -> 0.11736384
Y66: 83 | AB66: 0 | AE66: =AB66*Y66 -> 0
AN67: 83 | AQ67: 3 | AT67: =AQ67*AN67 -> 249
Y69: 84 | AB69: 0 | AE69: =AB69*Y69 -> 0
AN70: 84 | AT70: =AQ70*AN70 -> 0
AB81: =AB60+AB63+AB66+AB69+AB72+AB75+AB78 -> 0 | AE81: =AE60+AE63+AE66+AE69+AE72+AE75+AE78 -> 0
AQ82: =AQ61+AQ64+AQ67+AQ70+AQ73+AQ76+AQ79 -> 4 | AT82: =AT61+AT64+AT67+AT70+AT73+AT76+AT79 -> 331

Sheet 06-131
A2: PIER 1 - PRE STAGE 1 PERMANENT (P1-10) | P2: PIER 1 - PRE STAGE 1 TEMPORARY (TP1-3) | AE2: PIER 2 - PRE STAGE 1 PERMANENT (P2-20) | AT2: PIER 2 - PRE STAGE 1 TEMPORARY (TP2-3)
A3: "E" BOT | F3: "D" MID | K3: "A" TOP | P3: "E" BOT | U3: "D" MID | Z3: "A" TOP | AE3: "E" BOT | AJ3: "D" MID | AO3: "A" TOP | AT3: "E" BOT | AY3: "D" MID | BD3: "A" TOP
A4: Repair Rate : | C4: =B7/((42*3.1415/59)*(55/3.281)) -> 0.054881748 | F4: Repair Rate : | H4: =G7/((42*3.1415/59)*(50/3.281)) -> 0 | K4: ="Repair R: " & TEXT(L7/((42*3.1415/59)*(65/3.281)), "0.00%") -> Repair R: 0.00% | M4: Coating | P4: Repair Rate : | R4: =Q7/((42*3.1415/59)*(55/3.281)) -> 2.6675293e-09 | U4: Repair Rate : | W4: =V7/((42*3.1415/59)*(60/3.281)) -> 0 | Z4: Repair Rate : | AB4: =AA7/((42*3.1415/59)*(55/3.281)) -> 2.6675293e-15 | AE4: Repair Rate : | AG4: =AF7/((42*3.1415/59)*(55/3.281)) -> 2.6675293e-09 | AJ4: Repair Rate : | AL4: =AK7/((42*3.1415/59)*(60/3.281)) -> 0 | AO4: ="Repair R: " & TEXT(AP7/((42*3.1415/59)*(65/3.281)), "0.00%") -> Repair R: 0.00% | AQ4: Coating | AT4: Repair Rate : | AV4: =AU7/((42*3.1415/59)*(55/3.281)) -> 0.0067755244 | AY4: Repair Rate : | BA4: =AZ7/((42*3.1415/59)*(60/3.281)) -> 0.0055898076 | BD4: Repair Rate : | BF4: =BE7/((42*3.1415/59)*(55/3.281)) -> 0
A5: Drive Shoe (1) | F5: Back-Up Ring (1) | H5: Fused S. Rings (2) | K5: Back-Up Ring (1) | M5: Fused S. Rings (2) | P5: Drive Shoe (1) | U5: Back-Up Ring (1) | W5: Fused S. Rings (2) | Z5: Back-Up Ring (1) | AB5: Fused S. Rings (2) | AE5: Drive Shoe (1) | AJ5: Back-Up Ring (1) | AL5: Fused S. Rings (2) | AO5: Back-Up Ring (1) | AQ5: Fused S. Rings (2) | AT5: Drive Shoe (1) | AY5: Back-Up Ring (1) | BA5: Fused S. Rings (2) | BD5: Back-Up Ring (1) | BF5: Fused S. Rings (2)
A6: 55 ft | B6: 30 | F6: 50 ft | G6: 55 | K6: 65 ft | L6: 23 | P6: 55 ft | Q6: 41 | U6: 60 ft | V6: 36 | Z6: 55 ft | AA6: 32 | AE6: 55 ft | AF6: 50 | AJ6: 60 ft | AK6: 35 | AO6: 65 ft | AP6: 24 | AT6: 55 ft | AU6: 53 | AY6: 60 ft | AZ6: 37 | BD6: 55 ft | BE6: 43
B7: 2.0574 | C7: m. | E7: B.E | H7: m. | J7: B.E | M7: m. | O7: B.E | Q7: 1e-07 | R7: m. | S7: 1 | T7: B.E | W7: m. | Y7: B.E | AA7: 1e-13 | AB7: m. | AC7: 1 | AD7: B.E | AF7: 1e-07 | AG7: m. | AH7: 1 | AI7: B.E | AL7: m. | AN7: B.E | AQ7: m. | AS7: B.E | AU7: 0.254 | AV7: m. | AW7: 1 | AX7: B.E | AZ7: 0.2286 | BA7: m. | BC7: B.E | BF7: m. | BH7: B.E
A8: PIER 1 - PRE STAGE 1 PERMANENT (P1-9) | P8: PIER 1 - PRE STAGE 1 PERMANENT (P1-19) | AE8: PIER 1 - PRE STAGE 1 PERMANENT (P1-20) | AT8: PIER 1 - PRE STAGE 1 TEMPORARY (TP1-5)
A9: "E" BOT | F9: "D" MID | K9: "A" TOP | P9: "E" BOT | U9: "D" MID | Z9: "A" TOP | AE9: "E" BOT | AJ9: "D" MID | AO9: "A" TOP | AT9: "E" BOT | AY9: "D" MID | BD9: "A" TOP
A10: Repair Rate : | C10: =B13/((42*3.1415/59)*(80/3.281)) -> 0 | F10: Repair Rate : | H10: =G13/((42*3.1415/59)*(35/3.281)) -> 0 | K10: ="Repair R: " & TEXT(L13/((42*3.1415/59)*(55/3.281)), "0.00%") -> Repair R: 0.00% | M10: Coating | P10: Repair Rate : | R10: =Q13/((42*3.1415/59)*(80/3.281)) -> 1.8339264e-09 | U10: Repair Rate : | W10: =V13/((42*3.1415/59)*(35/3.281)) -> 0 | Z10: ="Repair R: " & TEXT(AA13/((42*3.1415/59)*(55/3.281)), "0.00%") -> Repair R: 0.00% | AB10: Coating | AE10: Repair Rate : | AG10: =AF13/((42*3.1415/59)*(80/3.281)) -> 0.033538846 | AJ10: Repair Rate : | AL10: =AK13/((42*3.1415/59)*(35/3.281)) -> 0 | AO10: ="Repair R: " & TEXT(AP13/((42*3.1415/59)*(55/3.281)), "0.00%") -> Repair R: 0.00% | AQ10: Coating | AT10: Repair Rate : | AV10: =AU13/((42*3.1415/59)*(80/3.281)) -> 0.004658173 | AY10: Repair Rate : | BA10: =AZ13/((42*3.1415/59)*(35/3.281)) -> 0 | BD10: Repair Rate : | BF10: =BE13/((42*3.1415/59)*(55/3.281)) -> 2.6675293e-09
A11: Drive Shoe (1) | F11: Back-Up Ring (1) | H11: Fused S. Rings (2) | K11: Back-Up Ring (1) | M11: Fused S. Rings (2) | P11: Drive Shoe (1) | U11: Back-Up Ring (1) | W11: Fused S. Rings (2) | Z11: Back-Up Ring (1) | AB11: Fused S. Rings (2) | AE11: Drive Shoe (1) | AJ11: Back-Up Ring (1) | AL11: Fused S. Rings (2) | AO11: Back-Up Ring (1) | AQ11: Fused S. Rings (2) | AT11: Drive Shoe (1) | AY11: Back-Up Ring (1) | BA11: Fused S. Rings (2) | BD11: Back-Up Ring (1) | BF11: Fused S. Rings (2)
A12: 80 ft | B12: 4 | F12: 35 ft | G12: 68 | K12: 55 ft | L12: 42 | P12: 80 ft | Q12: 1 | U12: 35 ft | V12: 2 | Z12: 55 ft | AA12: 49 | AE12: 80 ft | AF12: 5 | AJ12: 35 ft | AK12: 57 | AO12: 55 ft | AP12: 44 | AT12: 80 ft | AU12: 13 | AY12: 35 ft | AZ12: 59 | BD12: 55 ft | BE12: 54
C13: m. | E13: B.E | H13: m. | J13: B.E | L13: 1e-08 | M13: m. | O13: B.E | Q13: 1e-07 | R13: m. | T13: B.E | W13: m. | Y13: B.E | AA13: 1e-11 | AB13: m. | AD13: B.E | AF13: 1.8288 | AG13: m. | AI13: B.E | AL13: m. | AN13: B.E | AP13: 1e-19 | AQ13: m. | AS13: B.E | AU13: 0.254 | AV13: m. | AW13: 1 | AX13: B.E | BA13: m. | BC13: B.E | BE13: 1e-07 | BF13: m. | BH13: B.E
A14: PIER 1 - PRE STAGE 1 TEMPORARY (TP1-6) | P14: PIER 1 - PRE STAGE 1 TEMPORARY (TP1-7) | AE14: PIER 1 - PRE STAGE 1 TEMPORARY (TP1-8) | AT14: PIER 1 - PRE STAGE 1 TEMPORARY (TP1-1)
A15: "E" BOT | F15: "D" MID | K15: "A" TOP | P15: "E" BOT | U15: "D" MID | Z15: "A" TOP | AE15: "E" BOT | AJ15: "D" MID | AO15: "A" TOP | AT15: "E" BOT | AY15: "D" MID | BD15: "A" TOP
A16: Repair Rate : | C16: =B19/((42*3.1415/59)*(80/3.281)) -> 0 | F16: Repair Rate : | H16: =G19/((42*3.1415/59)*(35/3.281)) -> 0 | K16: Repair Rate : | M16: =L19/((42*3.1415/59)*(55/3.281)) -> 0 | P16: Repair Rate : | R16: =Q19/((42*3.1415/59)*(80/3.281)) -> 0 | U16: Repair Rate : | W16: =V19/((42*3.1415/59)*(35/3.281)) -> 0 | Z16: Repair Rate : | AB16: =AA19/((42*3.1415/59)*(55/3.281)) -> 0 | AE16: Repair Rate : | AG16: =AF19/((42*3.1415/59)*(80/3.281)) -> 0 | AJ16: Repair Rate : | AL16: =AK19/((42*3.1415/59)*(35/3.281)) -> 0 | AO16: Repair Rate : | AQ16: =AP19/((42*3.1415/59)*(55/3.281)) -> 0.014228601 | AT16: Repair Rate : | AV16: =AU19/((42*3.1415/59)*(80/3.281)) -> 0 | AY16: Repair Rate : | BA16: =AZ19/((42*3.1415/59)*(35/3.281)) -> 0 | BD16: Repair Rate : | BF16: =BE19/((42*3.1415/59)*(55/3.281)) -> 0.0040653147
A17: Drive Shoe (1) | F17: Back-Up Ring (1) | H17: Fused S. Rings (2) | K17: Back-Up Ring (1) | M17: Fused S. Rings (2) | P17: Drive Shoe (1) | U17: Back-Up Ring (1) | W17: Fused S. Rings (2) | Z17: Back-Up Ring (1) | AB17: Fused S. Rings (2) | AE17: Drive Shoe (1) | AJ17: Back-Up Ring (1) | AL17: Fused S. Rings (2) | AO17: Back-Up Ring (1) | AQ17: Fused S. Rings (2) | AT17: Drive Shoe (1) | AY17: Back-Up Ring (1) | BA17: Fused S. Rings (2) | BD17: Back-Up Ring (1) | BF17: Fused S. Rings (2)
A18: 80 ft | B18: 14 | F18: 35 ft | G18: 58 | K18: 55 ft | L18: 3 | P18: 80 ft | Q18: 18 | U18: 35 ft | V18: 60 | Z18: 55 ft | AA18: 34 | AE18: 80 ft | AF18: 21 | AJ18: 35 ft | AK18: 61 | AO18: 55 ft | AP18: 38 | AT18: 80 ft | AU18: 17 | AY18: 35 ft | AZ18: 72 | BD18: 55 ft | BE18: 40
C19: m. | E19: B.E | H19: m. | J19: B.E | M19: m. | O19: B.E | R19: m. | T19: B.E | W19: m. | Y19: B.E | AB19: m. | AD19: B.E | AG19: m. | AI19: B.E | AL19: m. | AN19: B.E | AP19: 0.5334 | AQ19: m. | AS19: B.E | AV19: m. | AX19: B.E | BA19: m. | BC19: B.E | BE19: 0.1524 | BF19: m. | BH19: B.E
A20: PIER 1 - PRE STAGE 1 TEMPORARY (TP1-2) | P20: PIER 1 - PRE STAGE 1 TEMPORARY (TP1-4) | AE20: PIER 2 - PRE STAGE 1 TEMPORARY (TP2-1) | AT20: PIER 2 - PRE STAGE 1 TEMPORARY (TP2-2)
A21: "E" BOT | F21: "D" MID | K21: "A" TOP | P21: "E" BOT | U21: "D" MID | Z21: "A" TOP | AE21: "E" BOT | AJ21: "D" MID | AO21: "A" TOP | AT21: "E" BOT | AY21: "D" MID | BD21: "A" TOP
A22: Repair Rate : | C22: =B25/((42*3.1415/59)*(80/3.281)) -> 0 | F22: Repair Rate : | H22: =G25/((42*3.1415/59)*(35/3.281)) -> 0 | K22: Repair Rate : | M22: =L25/((42*3.1415/59)*(55/3.281)) -> 0 | P22: Repair Rate : | R22: =Q25/((42*3.1415/59)*(80/3.281)) -> 0.029812307 | U22: Repair Rate : | W22: =V25/((42*3.1415/59)*(35/3.281)) -> 0 | Z22: Repair Rate : | AB22: =AA25/((42*3.1415/59)*(55/3.281)) -> 0.08333895 | AE22: Repair Rate : | AG22: =AF25/((42*3.1415/59)*(80/3.281)) -> 0 | AJ22: Repair Rate : | AL22: =AK25/((42*3.1415/59)*(35/3.281)) -> 0 | AO22: Repair Rate : | AQ22: =AP25/((42*3.1415/59)*(55/3.281)) -> 0 | AT22: Repair Rate : | AV22: =AU25/((42*3.1415/59)*(80/3.281)) -> 0 | AY22: Repair Rate : | BA22: =AZ25/((42*3.1415/59)*(35/3.281)) -> 0 | BD22: Repair Rate : | BF22: =BE25/((42*3.1415/59)*(55/3.281)) -> 0
A23: Drive Shoe (1) | F23: Back-Up Ring (1) | H23: Fused S. Rings (2) | K23: Back-Up Ring (1) | M23: Fused S. Rings (2) | P23: Drive Shoe (1) | U23: Back-Up Ring (1) | W23: Fused S. Rings (2) | Z23: Back-Up Ring (1) | AB23: Fused S. Rings (2) | AE23: Drive Shoe (1) | AJ23: Back-Up Ring (1) | AL23: Fused S. Rings (2) | AO23: Back-Up Ring (1) | AQ23: Fused S. Rings (2) | AT23: Drive Shoe (1) | AY23: Back-Up Ring (1) | BA23: Fused S. Rings (2) | BD23: Back-Up Ring (1) | BF23: Fused S. Rings (2)
A24: 80 ft | B24: 11 | F24: 35 ft | G24: 25 | K24: 55 ft | L24: 33 | P24: 80 ft | Q24: 12 | U24: 35 ft | V24: 26 | Z24: 55 ft | AA24: 31 | AE24: 80 ft | AF24: 16 | AJ24: 35 ft | AK24: 69 | AO24: 55 ft | AP24: 46 | AT24: 80 ft | AU24: 19 | AY24: 35 ft | AZ24: 70 | BD24: 55 ft | BE24: 47
C25: m. | E25: B.E | H25: m. | J25: B.E | M25: m. | O25: B.E | Q25: 1.6256 | R25: m. | T25: B.E | W25: m. | Y25: B.E | AA25: 3.1242 | AB25: m. | AD25: B.E | AG25: m. | AI25: B.E | AL25: m. | AN25: B.E | AQ25: m. | AS25: B.E | AV25: m. | AX25: B.E | BA25: m. | BC25: B.E | BF25: m. | BH25: B.E
A26: PIER 2 - PRE STAGE 1 TEMPORARY (TP2-4) | P26: PIER 2 - PRE STAGE 1 TEMPORARY (TP2-5) | AE26: PIER 2 - PRE STAGE 1 TEMPORARY (TP2-6) | AT26: PIER 2 - PRE STAGE 1 TEMPORARY (TP2-7)
A27: "E" BOT | F27: "D" MID | K27: "A" TOP | P27: "E" BOT | U27: "D" MID | Z27: "A" TOP | AE27: "E" BOT | AJ27: "D" MID | AO27: "A" TOP | AT27: "E" BOT | AY27: "D" MID | BD27: "A" TOP
A28: Repair Rate : | C28: =B31/((42*3.1415/59)*(80/3.281)) -> 0 | F28: Repair Rate : | H28: =G31/((42*3.1415/59)*(35/3.281)) -> 0 | K28: Repair Rate : | M28: =L31/((42*3.1415/59)*(55/3.281)) -> 0 | P28: Repair Rate : | R28: =Q31/((42*3.1415/59)*(80/3.281)) -> 0 | U28: Repair Rate : | W28: =V31/((42*3.1415/59)*(35/3.281)) -> 0 | Z28: Repair Rate : | AB28: =AA31/((42*3.1415/59)*(55/3.281)) -> 0.0054204195 | AE28: Repair Rate : | AG28: =AF31/((42*3.1415/59)*(80/3.281)) -> 0 | AJ28: Repair Rate : | AL28: =AK31/((42*3.1415/59)*(35/3.281)) -> 0 | AO28: Repair Rate : | AQ28: =AP31/((42*3.1415/59)*(55/3.281)) -> 0 | AT28: Repair Rate : | AV28: =AU31/((42*3.1415/59)*(80/3.281)) -> 0 | AY28: Repair Rate : | BA28: =AZ31/((42*3.1415/59)*(35/3.281)) -> 0 | BD28: Repair Rate : | BF28: =BE31/((42*3.1415/59)*(55/3.281)) -> 0.037942937
A29: Drive Shoe (1) | F29: Back-Up Ring (1) | H29: Fused S. Rings (2) | K29: Back-Up Ring (1) | M29: Fused S. Rings (2) | P29: Drive Shoe (1) | U29: Back-Up Ring (1) | W29: Fused S. Rings (2) | Z29: Back-Up Ring (1) | AB29: Fused S. Rings (2) | AE29: Drive Shoe (1) | AJ29: Back-Up Ring (1) | AL29: Fused S. Rings (2) | AO29: Back-Up Ring (1) | AQ29: Fused S. Rings (2) | AT29: Drive Shoe (1) | AY29: Back-Up Ring (1) | BA29: Fused S. Rings (2) | BD29: Back-Up Ring (1) | BF29: Fused S. Rings (2)
A30: 80 ft | B30: 7 | F30: 35 ft | G30: 64 | K30: 55 ft | L30: 48 | P30: 80 ft | Q30: 9 | U30: 35 ft | V30: 63 | Z30: 55 ft | AA30: 51 | AE30: 80 ft | AF30: 10 | AJ30: 35 ft | AK30: 66 | AO30: 55 ft | AP30: 52 | AT30: 80 ft | AU30: 15 | AY30: 35 ft | AZ30: 65 | BD30: 55 ft | BE30: 39
C31: m. | E31: B.E | H31: m. | J31: B.E | M31: m. | O31: B.E | R31: m. | T31: B.E | W31: m. | Y31: B.E | AA31: 0.2032 | AB31: m. | AD31: B.E | AG31: m. | AI31: B.E | AL31: m. | AN31: B.E | AQ31: m. | AS31: B.E | AV31: m. | AX31: B.E | BA31: m. | BC31: B.E | BE31: 1.4224 | BF31: m. | BG31: 1 | BH31: B.E
A32: PIER 2 - PRE STAGE 1 TEMPORARY (TP2-8) | P32: PIER 2 - PRE STAGE 1 PERMANENT (P2-19) | AE32: PIER 2 - PRE STAGE 1 PERMANENT (P2-9) | AT32: PIER 2 - PRE STAGE 1 PERMANENT (P2-10)
